Workbook

Sheet Cover
A1: EAINT-12341 — Test Cases (SRD v1.3)
A3: Ticket | B3: EAINT-12341 — [eAuto-BackEnd & UCD] Replace Approved Application Email with New Emails to UCD and RHB Support
A4: Link | B4: https://mfservices.atlassian.net/browse/EAINT-12341
A5: Baseline | B5: SRD_EAINT-12341_v1.3_20260929 (v1.3, 29.09.2026, Chee Mei Jia) · Email Template V3.0 (29.09.2026) · Appointment Letter Template v2.0 (18.09.2026)
A6: Release | B6: S34.X-20261008 (08.10.2026)
A7: Environment | B7: Staging — https://staging.eauto.my (VPN). Emails checked in Mailtrap only.
A8: QA | B8: Siti Nur Azila, Muhammad Amirul Azfar
A9: Objective | B9: On Application approval, every UCD gets ONE combined RHB Account Registration Guideline email (online + branch options) with the Appointment Letter attached, whatever its business type, number of directors or nationality; and RHB Support gets the Appointment Letter email with the UCD and apply@eauto.my copied.
A10: How the sheet is ordered | B10: Sheet 'Test Cases' is sorted by BUSINESS TYPE (colour band), then by RUN (CH1, CH2…), then by test area. Test case id = <run>-<number>, e.g. CH1-07. 'xx-07' in notes means test 07 of every run.
A11: How to execute | B11: 1) Do the run's '-01' (test data) and '-02' (robot run). 2) Check the emails and letter for its other test cases. 3) Fill Actual Result, Test Result (dropdown), Tested By, Test Date, Evidence, Defect ID, Remarks. Progress updates by itself in sheet 'Test Progress'.
A13: Legend — business type (band colour)
A14: Sdn Bhd / Bhd | B14: CH1, CH2
A15: Sole Proprietorship / Partnership | B15: CH3, CH4, CH5
A16: LLP | B16: CH6
A17: Business Trading (Sabah) | B17: CH7
A18: Business Trading (Sarawak) | B18: CH8
A20: Legend — test area (column 'Test Area')
A21: Setup & Flow | B21: Test data in eSim / sheet, and the robot run up to approval.
A22: Guideline Email (UCD) | B22: Email Template 1 (combined) to the UCD.
A23: RHB Support Email | B23: Email Template 3 to BIS.Support@rhbgroup.com.
A24: Appointment Letter | B24: The generated letter attached to both emails.
A25: Negative & Regression | B25: Things that must NOT happen, and existing behaviour that must not change.
A27: Legend — test result
A28: Pass | B28: Actual = expected.
A29: Fail | B29: Actual ≠ expected — raise a QA issue and put its id in Defect ID.
A30: Blocked | B30: Cannot be executed (environment, data, open question).
A31: Not Run | B31: Not executed yet (default).
A32: N/A | B32: Does not apply (explain in Remarks).
A33: TC id in red | B33: Expected result still pending confirmation — see the question in Remarks and sheet 'Open Questions'.

Sheet Test Progress
A1: Test Progress — updates by itself from sheet 'Test Cases' (column 'Test Result')
A3: By business type | B3: Total | C3: Pass | D3: Fail | E3: Blocked | F3: Not Run | G3: N/A | H3: Executed % | I3: Pass %
A4: Sdn Bhd / Bhd | B4: =COUNTIFS('Test Cases'!$C$4:$C$155,"Sdn Bhd / Bhd") | C4: =COUNTIFS('Test Cases'!$C$4:$C$155,"Sdn Bhd / Bhd",'Test Cases'!$N$4:$N$155,"Pass") | D4: =COUNTIFS('Test Cases'!$C$4:$C$155,"Sdn Bhd / Bhd",'Test Cases'!$N$4:$N$155,"Fail") | E4: =COUNTIFS('Test Cases'!$C$4:$C$155,"Sdn Bhd / Bhd",'Test Cases'!$N$4:$N$155,"Blocked") | F4: =COUNTIFS('Test Cases'!$C$4:$C$155,"Sdn Bhd / Bhd",'Test Cases'!$N$4:$N$155,"Not Run") | G4: =COUNTIFS('Test Cases'!$C$4:$C$155,"Sdn Bhd / Bhd",'Test Cases'!$N$4:$N$155,"N/A") | H4: =IF(B4=0,0,(C4+D4+E4)/B4) | I4: =IF((C4+D4)=0,0,C4/(C4+D4))
A5: Sole Proprietorship / Partnership | B5: =COUNTIFS('Test Cases'!$C$4:$C$155,"Sole Proprietorship / Partnership") | C5: =COUNTIFS('Test Cases'!$C$4:$C$155,"Sole Proprietorship / Partnership",'Test Cases'!$N$4:$N$155,"Pass") | D5: =COUNTIFS('Test Cases'!$C$4:$C$155,"Sole Proprietorship / Partnership",'Test Cases'!$N$4:$N$155,"Fail") | E5: =COUNTIFS('Test Cases'!$C$4:$C$155,"Sole Proprietorship / Partnership",'Test Cases'!$N$4:$N$155,"Blocked") | F5: =COUNTIFS('Test Cases'!$C$4:$C$155,"Sole Proprietorship / Partnership",'Test Cases'!$N$4:$N$155,"Not Run") | G5: =COUNTIFS('Test Cases'!$C$4:$C$155,"Sole Proprietorship / Partnership",'Test Cases'!$N$4:$N$155,"N/A") | H5: =IF(B5=0,0,(C5+D5+E5)/B5) | I5: =IF((C5+D5)=0,0,C5/(C5+D5))
A6: LLP | B6: =COUNTIFS('Test Cases'!$C$4:$C$155,"LLP") | C6: =COUNTIFS('Test Cases'!$C$4:$C$155,"LLP",'Test Cases'!$N$4:$N$155,"Pass") | D6: =COUNTIFS('Test Cases'!$C$4:$C$155,"LLP",'Test Cases'!$N$4:$N$155,"Fail") | E6: =COUNTIFS('Test Cases'!$C$4:$C$155,"LLP",'Test Cases'!$N$4:$N$155,"Blocked") | F6: =COUNTIFS('Test Cases'!$C$4:$C$155,"LLP",'Test Cases'!$N$4:$N$155,"Not Run") | G6: =COUNTIFS('Test Cases'!$C$4:$C$155,"LLP",'Test Cases'!$N$4:$N$155,"N/A") | H6: =IF(B6=0,0,(C6+D6+E6)/B6) | I6: =IF((C6+D6)=0,0,C6/(C6+D6))
A7: Business Trading (Sabah) | B7: =COUNTIFS('Test Cases'!$C$4:$C$155,"Business Trading (Sabah)") | C7: =COUNTIFS('Test Cases'!$C$4:$C$155,"Business Trading (Sabah)",'Test Cases'!$N$4:$N$155,"Pass") | D7: =COUNTIFS('Test Cases'!$C$4:$C$155,"Business Trading (Sabah)",'Test Cases'!$N$4:$N$155,"Fail") | E7: =COUNTIFS('Test Cases'!$C$4:$C$155,"Business Trading (Sabah)",'Test Cases'!$N$4:$N$155,"Blocked") | F7: =COUNTIFS('Test Cases'!$C$4:$C$155,"Business Trading (Sabah)",'Test Cases'!$N$4:$N$155,"Not Run") | G7: =COUNTIFS('Test Cases'!$C$4:$C$155,"Business Trading (Sabah)",'Test Cases'!$N$4:$N$155,"N/A") | H7: =IF(B7=0,0,(C7+D7+E7)/B7) | I7: =IF((C7+D7)=0,0,C7/(C7+D7))
A8: Business Trading (Sarawak) | B8: =COUNTIFS('Test Cases'!$C$4:$C$155,"Business Trading (Sarawak)") | C8: =COUNTIFS('Test Cases'!$C$4:$C$155,"Business Trading (Sarawak)",'Test Cases'!$N$4:$N$155,"Pass") | D8: =COUNTIFS('Test Cases'!$C$4:$C$155,"Business Trading (Sarawak)",'Test Cases'!$N$4:$N$155,"Fail") | E8: =COUNTIFS('Test Cases'!$C$4:$C$155,"Business Trading (Sarawak)",'Test Cases'!$N$4:$N$155,"Blocked") | F8: =COUNTIFS('Test Cases'!$C$4:$C$155,"Business Trading (Sarawak)",'Test Cases'!$N$4:$N$155,"Not Run") | G8: =COUNTIFS('Test Cases'!$C$4:$C$155,"Business Trading (Sarawak)",'Test Cases'!$N$4:$N$155,"N/A") | H8: =IF(B8=0,0,(C8+D8+E8)/B8) | I8: =IF((C8+D8)=0,0,C8/(C8+D8))
A9: TOTAL | B9: =SUM(B4:B8) | C9: =SUM(C4:C8) | D9: =SUM(D4:D8) | E9: =SUM(E4:E8) | F9: =SUM(F4:F8) | G9: =SUM(G4:G8) | H9: =IF(B9=0,0,(C9+D9+E9)/B9) | I9: =IF((C9+D9)=0,0,C9/(C9+D9))
A11: By run | B11: Total | C11: Pass | D11: Fail | E11: Blocked | F11: Not Run | G11: N/A | H11: Executed % | I11: Pass %
A12: CH1 | B12: =COUNTIFS('Test Cases'!$D$4:$D$155,"CH1") | C12: =COUNTIFS('Test Cases'!$D$4:$D$155,"CH1",'Test Cases'!$N$4:$N$155,"Pass") | D12: =COUNTIFS('Test Cases'!$D$4:$D$155,"CH1",'Test Cases'!$N$4:$N$155,"Fail") | E12: =COUNTIFS('Test Cases'!$D$4:$D$155,"CH1",'Test Cases'!$N$4:$N$155,"Blocked") | F12: =COUNTIFS('Test Cases'!$D$4:$D$155,"CH1",'Test Cases'!$N$4:$N$155,"Not Run") | G12: =COUNTIFS('Test Cases'!$D$4:$D$155,"CH1",'Test Cases'!$N$4:$N$155,"N/A") | H12: =IF(B12=0,0,(C12+D12+E12)/B12) | I12: =IF((C12+D12)=0,0,C12/(C12+D12))
A13: CH2 | B13: =COUNTIFS('Test Cases'!$D$4:$D$155,"CH2") | C13: =COUNTIFS('Test Cases'!$D$4:$D$155,"CH2",'Test Cases'!$N$4:$N$155,"Pass") | D13: =COUNTIFS('Test Cases'!$D$4:$D$155,"CH2",'Test Cases'!$N$4:$N$155,"Fail") | E13: =COUNTIFS('Test Cases'!$D$4:$D$155,"CH2",'Test Cases'!$N$4:$N$155,"Blocked") | F13: =COUNTIFS('Test Cases'!$D$4:$D$155,"CH2",'Test Cases'!$N$4:$N$155,"Not Run") | G13: =COUNTIFS('Test Cases'!$D$4:$D$155,"CH2",'Test Cases'!$N$4:$N$155,"N/A") | H13: =IF(B13=0,0,(C13+D13+E13)/B13) | I13: =IF((C13+D13)=0,0,C13/(C13+D13))
A14: CH3 | B14: =COUNTIFS('Test Cases'!$D$4:$D$155,"CH3") | C14: =COUNTIFS('Test Cases'!$D$4:$D$155,"CH3",'Test Cases'!$N$4:$N$155,"Pass") | D14: =COUNTIFS('Test Cases'!$D$4:$D$155,"CH3",'Test Cases'!$N$4:$N$155,"Fail") | E14: =COUNTIFS('Test Cases'!$D$4:$D$155,"CH3",'Test Cases'!$N$4:$N$155,"Blocked") | F14: =COUNTIFS('Test Cases'!$D$4:$D$155,"CH3",'Test Cases'!$N$4:$N$155,"Not Run") | G14: =COUNTIFS('Test Cases'!$D$4:$D$155,"CH3",'Test Cases'!$N$4:$N$155,"N/A") | H14: =IF(B14=0,0,(C14+D14+E14)/B14) | I14: =IF((C14+D14)=0,0,C14/(C14+D14))
A15: CH4 | B15: =COUNTIFS('Test Cases'!$D$4:$D$155,"CH4") | C15: =COUNTIFS('Test Cases'!$D$4:$D$155,"CH4",'Test Cases'!$N$4:$N$155,"Pass") | D15: =COUNTIFS('Test Cases'!$D$4:$D$155,"CH4",'Test Cases'!$N$4:$N$155,"Fail") | E15: =COUNTIFS('Test Cases'!$D$4:$D$155,"CH4",'Test Cases'!$N$4:$N$155,"Blocked") | F15: =COUNTIFS('Test Cases'!$D$4:$D$155,"CH4",'Test Cases'!$N$4:$N$155,"Not Run") | G15: =COUNTIFS('Test Cases'!$D$4:$D$155,"CH4",'Test Cases'!$N$4:$N$155,"N/A") | H15: =IF(B15=0,0,(C15+D15+E15)/B15) | I15: =IF((C15+D15)=0,0,C15/(C15+D15))
A16: CH5 | B16: =COUNTIFS('Test Cases'!$D$4:$D$155,"CH5") | C16: =COUNTIFS('Test Cases'!$D$4:$D$155,"CH5",'Test Cases'!$N$4:$N$155,"Pass") | D16: =COUNTIFS('Test Cases'!$D$4:$D$155,"CH5",'Test Cases'!$N$4:$N$155,"Fail") | E16: =COUNTIFS('Test Cases'!$D$4:$D$155,"CH5",'Test Cases'!$N$4:$N$155,"Blocked") | F16: =COUNTIFS('Test Cases'!$D$4:$D$155,"CH5",'Test Cases'!$N$4:$N$155,"Not Run") | G16: =COUNTIFS('Test Cases'!$D$4:$D$155,"CH5",'Test Cases'!$N$4:$N$155,"N/A") | H16: =IF(B16=0,0,(C16+D16+E16)/B16) | I16: =IF((C16+D16)=0,0,C16/(C16+D16))
A17: CH6 | B17: =COUNTIFS('Test Cases'!$D$4:$D$155,"CH6") | C17: =COUNTIFS('Test Cases'!$D$4:$D$155,"CH6",'Test Cases'!$N$4:$N$155,"Pass") | D17: =COUNTIFS('Test Cases'!$D$4:$D$155,"CH6",'Test Cases'!$N$4:$N$155,"Fail") | E17: =COUNTIFS('Test Cases'!$D$4:$D$155,"CH6",'Test Cases'!$N$4:$N$155,"Blocked") | F17: =COUNTIFS('Test Cases'!$D$4:$D$155,"CH6",'Test Cases'!$N$4:$N$155,"Not Run") | G17: =COUNTIFS('Test Cases'!$D$4:$D$155,"CH6",'Test Cases'!$N$4:$N$155,"N/A") | H17: =IF(B17=0,0,(C17+D17+E17)/B17) | I17: =IF((C17+D17)=0,0,C17/(C17+D17))
A18: CH7 | B18: =COUNTIFS('Test Cases'!$D$4:$D$155,"CH7") | C18: =COUNTIFS('Test Cases'!$D$4:$D$155,"CH7",'Test Cases'!$N$4:$N$155,"Pass") | D18: =COUNTIFS('Test Cases'!$D$4:$D$155,"CH7",'Test Cases'!$N$4:$N$155,"Fail") | E18: =COUNTIFS('Test Cases'!$D$4:$D$155,"CH7",'Test Cases'!$N$4:$N$155,"Blocked") | F18: =COUNTIFS('Test Cases'!$D$4:$D$155,"CH7",'Test Cases'!$N$4:$N$155,"Not Run") | G18: =COUNTIFS('Test Cases'!$D$4:$D$155,"CH7",'Test Cases'!$N$4:$N$155,"N/A") | H18: =IF(B18=0,0,(C18+D18+E18)/B18) | I18: =IF((C18+D18)=0,0,C18/(C18+D18))
A19: CH8 | B19: =COUNTIFS('Test Cases'!$D$4:$D$155,"CH8") | C19: =COUNTIFS('Test Cases'!$D$4:$D$155,"CH8",'Test Cases'!$N$4:$N$155,"Pass") | D19: =COUNTIFS('Test Cases'!$D$4:$D$155,"CH8",'Test Cases'!$N$4:$N$155,"Fail") | E19: =COUNTIFS('Test Cases'!$D$4:$D$155,"CH8",'Test Cases'!$N$4:$N$155,"Blocked") | F19: =COUNTIFS('Test Cases'!$D$4:$D$155,"CH8",'Test Cases'!$N$4:$N$155,"Not Run") | G19: =COUNTIFS('Test Cases'!$D$4:$D$155,"CH8",'Test Cases'!$N$4:$N$155,"N/A") | H19: =IF(B19=0,0,(C19+D19+E19)/B19) | I19: =IF((C19+D19)=0,0,C19/(C19+D19))
A20: TOTAL | B20: =SUM(B12:B19) | C20: =SUM(C12:C19) | D20: =SUM(D12:D19) | E20: =SUM(E12:E19) | F20: =SUM(F12:F19) | G20: =SUM(G12:G19) | H20: =IF(B20=0,0,(C20+D20+E20)/B20) | I20: =IF((C20+D20)=0,0,C20/(C20+D20))
A22: By test area | B22: Total | C22: Pass | D22: Fail | E22: Blocked | F22: Not Run | G22: N/A | H22: Executed % | I22: Pass %
A23: Setup & Flow | B23: =COUNTIFS('Test Cases'!$E$4:$E$155,"Setup & Flow") | C23: =COUNTIFS('Test Cases'!$E$4:$E$155,"Setup & Flow",'Test Cases'!$N$4:$N$155,"Pass") | D23: =COUNTIFS('Test Cases'!$E$4:$E$155,"Setup & Flow",'Test Cases'!$N$4:$N$155,"Fail") | E23: =COUNTIFS('Test Cases'!$E$4:$E$155,"Setup & Flow",'Test Cases'!$N$4:$N$155,"Blocked") | F23: =COUNTIFS('Test Cases'!$E$4:$E$155,"Setup & Flow",'Test Cases'!$N$4:$N$155,"Not Run") | G23: =COUNTIFS('Test Cases'!$E$4:$E$155,"Setup & Flow",'Test Cases'!$N$4:$N$155,"N/A") | H23: =IF(B23=0,0,(C23+D23+E23)/B23) | I23: =IF((C23+D23)=0,0,C23/(C23+D23))
A24: Guideline Email (UCD) | B24: =COUNTIFS('Test Cases'!$E$4:$E$155,"Guideline Email (UCD)") | C24: =COUNTIFS('Test Cases'!$E$4:$E$155,"Guideline Email (UCD)",'Test Cases'!$N$4:$N$155,"Pass") | D24: =COUNTIFS('Test Cases'!$E$4:$E$155,"Guideline Email (UCD)",'Test Cases'!$N$4:$N$155,"Fail") | E24: =COUNTIFS('Test Cases'!$E$4:$E$155,"Guideline Email (UCD)",'Test Cases'!$N$4:$N$155,"Blocked") | F24: =COUNTIFS('Test Cases'!$E$4:$E$155,"Guideline Email (UCD)",'Test Cases'!$N$4:$N$155,"Not Run") | G24: =COUNTIFS('Test Cases'!$E$4:$E$155,"Guideline Email (UCD)",'Test Cases'!$N$4:$N$155,"N/A") | H24: =IF(B24=0,0,(C24+D24+E24)/B24) | I24: =IF((C24+D24)=0,0,C24/(C24+D24))
A25: RHB Support Email | B25: =COUNTIFS('Test Cases'!$E$4:$E$155,"RHB Support Email") | C25: =COUNTIFS('Test Cases'!$E$4:$E$155,"RHB Support Email",'Test Cases'!$N$4:$N$155,"Pass") | D25: =COUNTIFS('Test Cases'!$E$4:$E$155,"RHB Support Email",'Test Cases'!$N$4:$N$155,"Fail") | E25: =COUNTIFS('Test Cases'!$E$4:$E$155,"RHB Support Email",'Test Cases'!$N$4:$N$155,"Blocked") | F25: =COUNTIFS('Test Cases'!$E$4:$E$155,"RHB Support Email",'Test Cases'!$N$4:$N$155,"Not Run") | G25: =COUNTIFS('Test Cases'!$E$4:$E$155,"RHB Support Email",'Test Cases'!$N$4:$N$155,"N/A") | H25: =IF(B25=0,0,(C25+D25+E25)/B25) | I25: =IF((C25+D25)=0,0,C25/(C25+D25))
A26: Appointment Letter | B26: =COUNTIFS('Test Cases'!$E$4:$E$155,"Appointment Letter") | C26: =COUNTIFS('Test Cases'!$E$4:$E$155,"Appointment Letter",'Test Cases'!$N$4:$N$155,"Pass") | D26: =COUNTIFS('Test Cases'!$E$4:$E$155,"Appointment Letter",'Test Cases'!$N$4:$N$155,"Fail") | E26: =COUNTIFS('Test Cases'!$E$4:$E$155,"Appointment Letter",'Test Cases'!$N$4:$N$155,"Blocked") | F26: =COUNTIFS('Test Cases'!$E$4:$E$155,"Appointment Letter",'Test Cases'!$N$4:$N$155,"Not Run") | G26: =COUNTIFS('Test Cases'!$E$4:$E$155,"Appointment Letter",'Test Cases'!$N$4:$N$155,"N/A") | H26: =IF(B26=0,0,(C26+D26+E26)/B26) | I26: =IF((C26+D26)=0,0,C26/(C26+D26))
A27: Negative & Regression | B27: =COUNTIFS('Test Cases'!$E$4:$E$155,"Negative & Regression") | C27: =COUNTIFS('Test Cases'!$E$4:$E$155,"Negative & Regression",'Test Cases'!$N$4:$N$155,"Pass") | D27: =COUNTIFS('Test Cases'!$E$4:$E$155,"Negative & Regression",'Test Cases'!$N$4:$N$155,"Fail") | E27: =COUNTIFS('Test Cases'!$E$4:$E$155,"Negative & Regression",'Test Cases'!$N$4:$N$155,"Blocked") | F27: =COUNTIFS('Test Cases'!$E$4:$E$155,"Negative & Regression",'Test Cases'!$N$4:$N$155,"Not Run") | G27: =COUNTIFS('Test Cases'!$E$4:$E$155,"Negative & Regression",'Test Cases'!$N$4:$N$155,"N/A") | H27: =IF(B27=0,0,(C27+D27+E27)/B27) | I27: =IF((C27+D27)=0,0,C27/(C27+D27))
A28: TOTAL | B28: =SUM(B23:B27) | C28: =SUM(C23:C27) | D28: =SUM(D23:D27) | E28: =SUM(E23:E27) | F28: =SUM(F23:F27) | G28: =SUM(G23:G27) | H28: =IF(B28=0,0,(C28+D28+E28)/B28) | I28: =IF((C28+D28)=0,0,C28/(C28+D28))
A30: Executed % = (Pass + Fail + Blocked) / Total. Pass % = Pass / (Pass + Fail).

Sheet Test Cases
A1: No. | B1: TC ID | C1: Business Type | D1: Run | E1: Test Area | F1: Test Scenario | G1: Pre-condition / Test Data | H1: Test Steps | I1: Expected Result | J1: Requirement | K1: Priority | L1: Test Type | M1: Actual Result | N1: Test Result | O1: Tested By (QA) | P1: Test Date | Q1: Evidence (screenshot / file) | R1: Defect ID | S1: Remarks
A2: SDN BHD / BHD — 2 run(s)
A3: Run CH1 · 4 directors, all Malaysian · TIN starts with C · Main run — do it first. Carries the extra checks CH1-20 (old email) and CH1-21 (hardcopy regression).
A4: 1 | B4: CH1-01 | C4: Sdn Bhd / Bhd | D4: CH1 | E4: Setup & Flow | F4: eSim set up for CH1 — Sdn Bhd / Bhd, 4 directors, all Malaysian | G4: A PASS company from the checker sheet (TIN starts with C) typed in tab '1 Companies'. VPN on. | H4: 1. Log in to eSim: https://172.30.202.114:9089/esim/login. 2. Open tab 'CH1' of EAINT-12341_eSim_Setup.xlsx. 3. Screen 'Ssm Enquiry Resp': type every value of Part A, then Save. 4. Submission screen: type every value of Part B (including the tags and the people), then Save. 5. Screenshot both saved records. | I4: 1. Ssm Enquiry Resp saved with Response Code 004, the ROC without its letter, the 12-digit number, Delay 0. 2. Submission record saved with Response Code 005, status ACTIVE/EXISTING and exactly 4 directors. 3. No error message on save. | J4: Test data (eSimulator guide) | K4: High | L4: Setup | N4: Not Run
A5: 2 | B5: CH1-02 | C5: Sdn Bhd / Bhd | D5: CH1 | E5: Setup & Flow | F5: Robot runs CH1 to Application Approved | G5: CH1-01 passed. VPN on. Settings file filled. Mailtrap open. | H5: 1. In the automation folder run: npm run ch1. 2. Tick 'I'm not a robot' when the window asks. 3. Pay in the payment window when the window asks. 4. Do not click anything else; wait for the end of the run. 5. Copy the black-window text and keep it with the evidence. | I5: 1. The Pre-Application is created, paid and approved (Pre-Application No P……/….. printed). 2. The Application is submitted and approved by the Approver (Application No NA…….. printed). 3. The window shows 'READY FOR MANUAL EMAIL CHECK' — stopped at Application Approved. 4. An expected-email file is created in 04-runs/. | J5: REQ-001 (trigger) | K5: High | L5: E2E flow (automation) | N5: Not Run
A6: 3 | B6: CH1-03 | C6: Sdn Bhd / Bhd | D6: CH1 | E6: Setup & Flow | F6: Pre-Application summary shows the SSM details set up in eSim | G6: CH1-02 reached at least Pre-Application approved. | H6: 1. BackOffice > Pre-Application listing: search the Pre-Application No. 2. Check the SSM Status column. 3. Open the record and its SSM details. | I6: 1. SSM Status = OK. 2. Registration no. = <ROC no. with letter> (<12-digit no.>) exactly as in tab '1 Companies' (letter not doubled, e.g. no '-U-A'). 3. The people listed match the eSim setup (4 directors, all Malaysian). 4. These are the values the Appointment Letter must use (old / new BRN). | J6: REQ-007 (letter data source) | K6: High | L6: Data | N6: Not Run
A7: 4 | B7: CH1-04 | C7: Sdn Bhd / Bhd | D7: CH1 | E7: Negative & Regression | F7: Pre-Application approval does NOT send the new emails | G7: CH1-02 reached at least Pre-Application approved. | H7: 1. Take the 'pre-app approved' and 'approved' (or 'submitted') times from the run log. 2. In Mailtrap, list all emails to the run's admin and director email addresses between those two times. | I7: 1. No 'RHB Online / Branch Account Opening' email in that window. 2. No 'Approved eAuto Registration' email in that window. 3. The existing Pre-Application approval email (with the Application link) still arrives as before. | J7: REQ-001 | K7: Medium | L7: Negative | N7: Not Run
A8: 5 | B8: CH1-05 | C8: Sdn Bhd / Bhd | D8: CH1 | E8: Guideline Email (UCD) | F8: Guideline email is received by the UCD — To and CC | G8: CH1-02 passed (Application Approved). Values from the run log (black window) block READY FOR MANUAL EMAIL CHECK and the expected-email file 04-runs/12341_CH1_<run>.md. | H8: 1. In Mailtrap, search the admin email and the director email from the run log. 2. Open the email whose subject starts 'RHB Online / Branch Account Opening'. 3. Open its headers (To, CC) and note the received time. | I8: 1. Exactly one such email for this Application. 2. To = the UCD email recorded in the Application — record WHICH address it is (admin or director, Q-04). 3. CC = apply@eauto.my. 4. Received after the 'approved' time in the run log. | J8: REQ-001, REQ-002 | K8: High | L8: Functional | N8: Not Run | S8: Sender (From) not checked — still pending Operations (Q-12).
A9: 6 | B9: CH1-06 | C9: Sdn Bhd / Bhd | D9: CH1 | E9: Guideline Email (UCD) | F9: Guideline email subject | G9: CH1-02 passed (Application Approved). Values from the run log (black window) block READY FOR MANUAL EMAIL CHECK and the expected-email file 04-runs/12341_CH1_<run>.md. | H9: 1. Open the guideline email. 2. Read the subject exactly as shown. | I9: 1. Subject = 'RHB Online / Branch Account Opening - <Application No> - <Company Name>'. 2. <Application No> = the NA number in the run log; <Company Name> = the run's company name. 3. Not the old v1.1 subjects 'RHB Online Account Opening - …' or 'RHB Branch Account Opening - …'. | J9: REQ-005 | K9: High | L9: Functional | N9: Not Run
A10: 7 | B10: CH1-07 | C10: Sdn Bhd / Bhd | D10: CH1 | E10: Guideline Email (UCD) | F10: Guideline email body — same combined template (online + branch options) | G10: CH1-02 passed (Application Approved). Values from the run log (black window) block READY FOR MANUAL EMAIL CHECK and the expected-email file 04-runs/12341_CH1_<run>.md. | H10: 1. Open the email body (HTML view). 2. Compare paragraph by paragraph with sheet 'Expected Templates' → 'Email Template 1 — Body' (or the 04-runs file). 3. Check the Text view too if Mailtrap shows one. | I10: 1. Every paragraph present, in order, same wording. 2. Application No and Company Name show the run's values. 3. Contains 'within three (3) working days', 'Option 1 – Online Account Opening' (with the four (4) users note and seven (7) days) and 'Option 2 – Account Opening at RHB Branch'. 4. Ends with the signature block (Thank you / Best regards / eAuto Sdn Bhd / address / Customer Service / WhatsApp) — Q-01. 5. Does NOT contain 'As your company meets the eligibility requirements…' nor 'Please bring the documents provided by RHB…'. | J10: REQ-005 | K10: High | L10: Functional | N10: Not Run | S10: Same expected text for every business type — REQ-005 Example 1 and Example 2 both send Email Template 1. Main run — do it first. Carries the extra checks CH1-20 (old email) and CH1-21 (hardcopy regression).
A11: 8 | B11: CH1-08 | C11: Sdn Bhd / Bhd | D11: CH1 | E11: Guideline Email (UCD) | F11: Links in the guideline email | G11: CH1-02 passed (Application Approved). Values from the run log (black window) block READY FOR MANUAL EMAIL CHECK and the expected-email file 04-runs/12341_CH1_<run>.md. | H11: 1. Hover over the link under 'Option 1 – Online Account Opening' and note the target. 2. Hover over the Application Link near the end. 3. Click the RHB link. 4. Open the Application Link in a fresh browser window. | I11: 1. Option 1 link target = https://smecaonline.rhbgroup.com/sme/online?tag=campaign. 2. The Application Link is a clickable URL, not the text '[Application Link]'. 3. The RHB link opens the RHB SME online page. 4. The Application Link opens the page agreed in Q-03 for THIS Application (no error page). | J11: REQ-005 | K11: High | L11: Functional | N11: Not Run | S11: Where the Application Link must land is not in the SRD (Q-03).
A12: 9 | B12: CH1-09 | C12: Sdn Bhd / Bhd | D12: CH1 | E12: Guideline Email (UCD) | F12: Appointment Letter attached to the guideline email | G12: CH1-02 passed (Application Approved). Values from the run log (black window) block READY FOR MANUAL EMAIL CHECK and the expected-email file 04-runs/12341_CH1_<run>.md. | H12: 1. Open the Attachments tab of the guideline email. 2. Note file name, type and size. 3. Download and open it. | I12: 1. Exactly one attachment: the Appointment Letter. 2. It opens without error. 3. It is for THIS Application (company name and Application No match). 4. No Offer Letter, Direct Debit form or Board of Resolution attached. | J12: REQ-008 | K12: High | L12: Functional | N12: Not Run | S12: File type and name not specified (Q-08) — record them.
A13: 10 | B13: CH1-10 | C13: Sdn Bhd / Bhd | D13: CH1 | E13: Guideline Email (UCD) | F13: Removed templates are not sent | G13: CH1-02 passed (Application Approved). Values from the run log (black window) block READY FOR MANUAL EMAIL CHECK and the expected-email file 04-runs/12341_CH1_<run>.md. | H13: 1. In Mailtrap, list every email to the run's addresses after the 'approved' time. | I13: 1. No email with subject 'RHB Branch Account Opening - …' (old Email Template 2). 2. No email with subject 'RHB Online Account Opening - …' without '/ Branch' (old Email Template 1). | J13: REQ-003 / REQ-004 removed, REQ-005 | K13: Medium | L13: Negative | N13: Not Run
A14: 11 | B14: CH1-11 | C14: Sdn Bhd / Bhd | D14: CH1 | E14: RHB Support Email | F14: RHB Support email — To and CC | G14: CH1-02 passed (Application Approved). Values from the run log (black window) block READY FOR MANUAL EMAIL CHECK and the expected-email file 04-runs/12341_CH1_<run>.md. | H14: 1. In Mailtrap, search the run's admin / director email (it is in CC of this email). 2. Open the email whose subject starts 'Approved eAuto Registration'. 3. Open its headers. | I14: 1. To = BIS.Support@rhbgroup.com. 2. CC contains the UCD email recorded in the Application AND apply@eauto.my. 3. Received after the 'approved' time. 4. The email is in Mailtrap only — nothing reached RHB (Q-17). | J14: REQ-006 | K14: High | L14: Functional | N14: Not Run
A15: 12 | B15: CH1-12 | C15: Sdn Bhd / Bhd | D15: CH1 | E15: RHB Support Email | F15: RHB Support email subject | G15: CH1-02 passed (Application Approved). Values from the run log (black window) block READY FOR MANUAL EMAIL CHECK and the expected-email file 04-runs/12341_CH1_<run>.md. | H15: 1. Open the RHB Support email. 2. Read the subject. | I15: 1. Subject = 'Approved eAuto Registration - <Company Name> - <BRN Number>'. 2. <Company Name> = the run's company name. 3. <BRN Number> = the number agreed in Q-05 (SRD example shows the 12-digit new number) — record which one. | J15: REQ-009 | K15: High | L15: Functional | N15: Not Run
A16: 13 | B16: CH1-13 | C16: Sdn Bhd / Bhd | D16: CH1 | E16: RHB Support Email | F16: RHB Support email body — values and wording | G16: CH1-02 passed (Application Approved). Values from the run log (black window) block READY FOR MANUAL EMAIL CHECK and the expected-email file 04-runs/12341_CH1_<run>.md. | H16: 1. Open the body. 2. Compare with sheet 'Expected Templates' → 'Email Template 3 — Body'. 3. Compare each value line with the Application. | I16: 1. Every paragraph present, in order, same wording (1 working day request, Reply All instruction, signature block). 2. Company Name / Business Registration Number / UCD Contact Person / Contact Number / Email Address show the Application's values (which contact: Q-04). 3. Does NOT contain 'The above company is not eligible for RHB's online account-opening process…'. | J16: REQ-009 | K16: High | L16: Functional | N16: Not Run | S16: The robot uses different name / mobile / email for Admin and Director, so this email shows which one the system takes (Q-04).
A17: 14 | B17: CH1-14 | C17: Sdn Bhd / Bhd | D17: CH1 | E17: RHB Support Email | F17: Appointment Letter attached to the RHB Support email | G17: CH1-02 passed (Application Approved). Values from the run log (black window) block READY FOR MANUAL EMAIL CHECK and the expected-email file 04-runs/12341_CH1_<run>.md. | H17: 1. Open the Attachments tab. 2. Download and open the attachment. | I17: 1. Exactly one attachment: the Appointment Letter for THIS Application. 2. It opens without error. | J17: REQ-008 | K17: High | L17: Functional | N17: Not Run
A18: 15 | B18: CH1-15 | C18: Sdn Bhd / Bhd | D18: CH1 | E18: Appointment Letter | F18: Appointment Letter layout and fixed text | G18: CH1-02 passed (Application Approved). Values from the run log (black window) block READY FOR MANUAL EMAIL CHECK and the expected-email file 04-runs/12341_CH1_<run>.md. | H18: 1. Open the letter from the guideline email. 2. Compare with sheet 'Expected Templates' → 'Appointment Letter' and with Sample_Appointment_Letter_v2.0. 3. Check header, body, signature and footer on every page. | I18: 1. Title 'LETTER OF CONFIRMATION OF REGISTRATION AS A USED CAR DEALER (UCD) UNDER eAUTO SDN. BHD. PLATFORM' (spacing: Q-10). 2. Letterhead: eAuto logo, 'eAuto Sdn Bhd 200401038456 (676967-T)', address, 'Tel: 03-2779 8893'. 3. Clauses 1–8 numbered, wording as the template; Clause 6 refers to 'Clause 5'. 4. Registration details table (UCD Name / Company Registration No. / UCD / Dealer Reference No.). 5. Signature image, 'CHIA KET MING', 'COO'; footer 'Website: www.eauto.my | Customer Service: 03-2779 8899 | Email: support@eauto.my'. 6. No layout break (cut text, overlap, blank page). | J18: REQ-007 | K18: High | L18: Functional | N18: Not Run
A19: 16 | B19: CH1-16 | C19: Sdn Bhd / Bhd | D19: CH1 | E19: Appointment Letter | F19: Appointment Letter pre-filled values | G19: CH1-02 passed (Application Approved). Values from the run log (black window) block READY FOR MANUAL EMAIL CHECK and the expected-email file 04-runs/12341_CH1_<run>.md. SSM details from CH1-03. | H19: 1. Open the letter. 2. Compare each value with its source (run log, Application, Pre-Application SSM details). | I19: 1. Date = Application approval date, DD/MM/YYYY. 2. Our Ref = eAuto/OPS/UCD/<Application No>/<approval year> (square brackets: Q-07). 3. UCD Company Name = the Application's company name (recipient block, Clause 1, Clause 4). 4. Company Registration No. = <ROC no. with letter> (<12-digit no.>), e.g. 1511229-A (202301017307) — identical in recipient block, Clause 1 and Clause 4. 5. Company Address = the Application's company address (which field: Q-06). 6. UCD / Dealer Reference No. = '<Pre-Application No> / <Application No>'. | J19: REQ-007 | K19: High | L19: Functional | N19: Not Run
A20: 17 | B20: CH1-17 | C20: Sdn Bhd / Bhd | D20: CH1 | E20: Appointment Letter | F20: Same Appointment Letter on both emails | G20: CH1-02 passed (Application Approved). Values from the run log (black window) block READY FOR MANUAL EMAIL CHECK and the expected-email file 04-runs/12341_CH1_<run>.md. | H20: 1. Download the attachment of the guideline email and of the RHB Support email. 2. Compare them. | I20: 1. Same file name and size. 2. Same Our Ref, date, company, registration number and reference numbers. | J20: REQ-008 | K20: Medium | L20: Functional | N20: Not Run
A21: 18 | B21: CH1-18 | C21: Sdn Bhd / Bhd | D21: CH1 | E21: Negative & Regression | F21: No unresolved placeholders anywhere | G21: CH1-02 passed (Application Approved). Values from the run log (black window) block READY FOR MANUAL EMAIL CHECK and the expected-email file 04-runs/12341_CH1_<run>.md. | H21: 1. In both emails, search the subject and body for '[' and ']'. 2. In the letter, search for '[' and ']'. | I21: 1. None of these appear literally: [Application No], [Company Name], [BRN Number], [Name], [Contact Number], [UCD Email Address], [RHB Online Registration Link], [Application Link], [DD/MM/YYYY], [YYYY], [UCD Company Name], [Old BRN], [New BRN], [Company Address], [Pre-Application No]. 2. No empty value (e.g. 'Company Name: ' with nothing after it). | J21: REQ-005, REQ-007, REQ-009 | K21: High | L21: Negative | N21: Not Run | S21: Brackets kept around a filled value in the letter are Q-07, not a failure here.
A22: 19 | B22: CH1-19 | C22: Sdn Bhd / Bhd | D22: CH1 | E22: Negative & Regression | F22: Exactly one of each email per approval (no duplicates) | G22: CH1-02 passed (Application Approved). Values from the run log (black window) block READY FOR MANUAL EMAIL CHECK and the expected-email file 04-runs/12341_CH1_<run>.md. | H22: 1. Wait 10 minutes after the 'approved' time (Q-16). 2. In Mailtrap, count the emails for this Application by subject. | I22: 1. Exactly 1 × 'RHB Online / Branch Account Opening - …'. 2. Exactly 1 × 'Approved eAuto Registration - …'. | J22: REQ-001 | K22: Medium | L22: Negative | N22: Not Run
A23: 20 | B23: CH1-20 | C23: Sdn Bhd / Bhd | D23: CH1 | E23: Negative & Regression | F23: Old approved-application email (3 RHB documents) is NOT sent | G23: CH1-02 passed (Application Approved). Values from the run log (black window) block READY FOR MANUAL EMAIL CHECK and the expected-email file 04-runs/12341_CH1_<run>.md. | H23: 1. In Mailtrap, list every email to the run's addresses after the 'approved' time. 2. Look for the old approved-application email (subject per Q-23). | I23: 1. The old email is not received. 2. No eAuto email carries the Offer Letter, Direct Debit form or Board of Resolution. | J23: REQ-001 | K23: High | L23: Regression / Negative | N23: Not Run
A24: 21 | B24: CH1-21 | C24: Sdn Bhd / Bhd | D24: CH1 | E24: Negative & Regression | F24: Hardcopy resubmission still works after approval (EAINT-11763) | G24: CH1-02 passed (Application Approved). Values from the run log (black window) block READY FOR MANUAL EMAIL CHECK and the expected-email file 04-runs/12341_CH1_<run>.md. Run AFTER all other CH1 checks (it sends more emails). | H24: 1. BackOffice > Application: open the run's Application > Registration Document. 2. Set Hardcopy Doc status to 'Pending UCD - Incomplete Docs' and click Update. 3. Click 'Request Hardcopy Resubmission', select documents, enter remarks, confirm. 4. In Mailtrap, open the resubmission email. | I24: 1. Application status shows Approved, as before the CR. 2. The popup and its document checklist work as before. 3. The resubmission email goes to the UCD, CC apply@eauto.my, BCC the Assignee. 4. The Reverted Reason shows on the Registration Document page. | J24: REQ-001 (approval handling unchanged) | K24: Medium | L24: Regression | N24: Not Run | S24: 'As before' reference: EAINT-11763 SRD / test sheet (Q-14).
A25: Run CH2 · 3 directors: 2 Malaysian + 1 foreigner · TIN starts with C · REQ-005 Example 2 (foreign director) — must get the SAME email as CH1.
A26: 22 | B26: CH2-01 | C26: Sdn Bhd / Bhd | D26: CH2 | E26: Setup & Flow | F26: eSim set up for CH2 — Sdn Bhd / Bhd, 3 directors: 2 Malaysian + 1 foreigner | G26: A PASS company from the checker sheet (TIN starts with C) typed in tab '1 Companies'. VPN on. | H26: 1. Log in to eSim: https://172.30.202.114:9089/esim/login. 2. Open tab 'CH2' of EAINT-12341_eSim_Setup.xlsx. 3. Screen 'Ssm Enquiry Resp': type every value of Part A, then Save. 4. Submission screen: type every value of Part B (including the tags and the people), then Save. 5. Screenshot both saved records. | I26: 1. Ssm Enquiry Resp saved with Response Code 004, the ROC without its letter, the 12-digit number, Delay 0. 2. Submission record saved with Response Code 005, status ACTIVE/EXISTING and exactly 3 directors. 3. No error message on save. | J26: Test data (eSimulator guide) | K26: High | L26: Setup | N26: Not Run
A27: 23 | B27: CH2-02 | C27: Sdn Bhd / Bhd | D27: CH2 | E27: Setup & Flow | F27: Robot runs CH2 to Application Approved | G27: CH2-01 passed. VPN on. Settings file filled. Mailtrap open. | H27: 1. In the automation folder run: npm run ch2. 2. Tick 'I'm not a robot' when the window asks. 3. Pay in the payment window when the window asks. 4. Do not click anything else; wait for the end of the run. 5. Copy the black-window text and keep it with the evidence. | I27: 1. The Pre-Application is created, paid and approved (Pre-Application No P……/….. printed). 2. The Application is submitted and approved by the Approver (Application No NA…….. printed). 3. The window shows 'READY FOR MANUAL EMAIL CHECK' — stopped at Application Approved. 4. An expected-email file is created in 04-runs/. | J27: REQ-001 (trigger) | K27: High | L27: E2E flow (automation) | N27: Not Run
A28: 24 | B28: CH2-03 | C28: Sdn Bhd / Bhd | D28: CH2 | E28: Setup & Flow | F28: Pre-Application summary shows the SSM details set up in eSim | G28: CH2-02 reached at least Pre-Application approved. | H28: 1. BackOffice > Pre-Application listing: search the Pre-Application No. 2. Check the SSM Status column. 3. Open the record and its SSM details. | I28: 1. SSM Status = OK. 2. Registration no. = <ROC no. with letter> (<12-digit no.>) exactly as in tab '1 Companies' (letter not doubled, e.g. no '-U-A'). 3. The people listed match the eSim setup (3 directors: 2 Malaysian + 1 foreigner). 4. These are the values the Appointment Letter must use (old / new BRN). | J28: REQ-007 (letter data source) | K28: High | L28: Data | N28: Not Run
A29: 25 | B29: CH2-04 | C29: Sdn Bhd / Bhd | D29: CH2 | E29: Negative & Regression | F29: Pre-Application approval does NOT send the new emails | G29: CH2-02 reached at least Pre-Application approved. | H29: 1. Take the 'pre-app approved' and 'approved' (or 'submitted') times from the run log. 2. In Mailtrap, list all emails to the run's admin and director email addresses between those two times. | I29: 1. No 'RHB Online / Branch Account Opening' email in that window. 2. No 'Approved eAuto Registration' email in that window. 3. The existing Pre-Application approval email (with the Application link) still arrives as before. | J29: REQ-001 | K29: Medium | L29: Negative | N29: Not Run
A30: 26 | B30: CH2-05 | C30: Sdn Bhd / Bhd | D30: CH2 | E30: Guideline Email (UCD) | F30: Guideline email is received by the UCD — To and CC | G30: CH2-02 passed (Application Approved). Values from the run log (black window) block READY FOR MANUAL EMAIL CHECK and the expected-email file 04-runs/12341_CH2_<run>.md. | H30: 1. In Mailtrap, search the admin email and the director email from the run log. 2. Open the email whose subject starts 'RHB Online / Branch Account Opening'. 3. Open its headers (To, CC) and note the received time. | I30: 1. Exactly one such email for this Application. 2. To = the UCD email recorded in the Application — record WHICH address it is (admin or director, Q-04). 3. CC = apply@eauto.my. 4. Received after the 'approved' time in the run log. | J30: REQ-001, REQ-002 | K30: High | L30: Functional | N30: Not Run | S30: Sender (From) not checked — still pending Operations (Q-12).
A31: 27 | B31: CH2-06 | C31: Sdn Bhd / Bhd | D31: CH2 | E31: Guideline Email (UCD) | F31: Guideline email subject | G31: CH2-02 passed (Application Approved). Values from the run log (black window) block READY FOR MANUAL EMAIL CHECK and the expected-email file 04-runs/12341_CH2_<run>.md. | H31: 1. Open the guideline email. 2. Read the subject exactly as shown. | I31: 1. Subject = 'RHB Online / Branch Account Opening - <Application No> - <Company Name>'. 2. <Application No> = the NA number in the run log; <Company Name> = the run's company name. 3. Not the old v1.1 subjects 'RHB Online Account Opening - …' or 'RHB Branch Account Opening - …'. | J31: REQ-005 | K31: High | L31: Functional | N31: Not Run
A32: 28 | B32: CH2-07 | C32: Sdn Bhd / Bhd | D32: CH2 | E32: Guideline Email (UCD) | F32: Guideline email body — same combined template (online + branch options) | G32: CH2-02 passed (Application Approved). Values from the run log (black window) block READY FOR MANUAL EMAIL CHECK and the expected-email file 04-runs/12341_CH2_<run>.md. | H32: 1. Open the email body (HTML view). 2. Compare paragraph by paragraph with sheet 'Expected Templates' → 'Email Template 1 — Body' (or the 04-runs file). 3. Check the Text view too if Mailtrap shows one. | I32: 1. Every paragraph present, in order, same wording. 2. Application No and Company Name show the run's values. 3. Contains 'within three (3) working days', 'Option 1 – Online Account Opening' (with the four (4) users note and seven (7) days) and 'Option 2 – Account Opening at RHB Branch'. 4. Ends with the signature block (Thank you / Best regards / eAuto Sdn Bhd / address / Customer Service / WhatsApp) — Q-01. 5. Does NOT contain 'As your company meets the eligibility requirements…' nor 'Please bring the documents provided by RHB…'. | J32: REQ-005 | K32: High | L32: Functional | N32: Not Run | S32: Same expected text for every business type — REQ-005 Example 1 and Example 2 both send Email Template 1. REQ-005 Example 2 (foreign director) — must get the SAME email as CH1.
A33: 29 | B33: CH2-08 | C33: Sdn Bhd / Bhd | D33: CH2 | E33: Guideline Email (UCD) | F33: Links in the guideline email | G33: CH2-02 passed (Application Approved). Values from the run log (black window) block READY FOR MANUAL EMAIL CHECK and the expected-email file 04-runs/12341_CH2_<run>.md. | H33: 1. Hover over the link under 'Option 1 – Online Account Opening' and note the target. 2. Hover over the Application Link near the end. | I33: 1. Option 1 link target = https://smecaonline.rhbgroup.com/sme/online?tag=campaign. 2. The Application Link is a clickable URL, not the text '[Application Link]'. | J33: REQ-005 | K33: Medium | L33: Functional | N33: Not Run | S33: Where the Application Link must land is not in the SRD (Q-03).
A34: 30 | B34: CH2-09 | C34: Sdn Bhd / Bhd | D34: CH2 | E34: Guideline Email (UCD) | F34: Appointment Letter attached to the guideline email | G34: CH2-02 passed (Application Approved). Values from the run log (black window) block READY FOR MANUAL EMAIL CHECK and the expected-email file 04-runs/12341_CH2_<run>.md. | H34: 1. Open the Attachments tab of the guideline email. 2. Note file name, type and size. 3. Download and open it. | I34: 1. Exactly one attachment: the Appointment Letter. 2. It opens without error. 3. It is for THIS Application (company name and Application No match). 4. No Offer Letter, Direct Debit form or Board of Resolution attached. | J34: REQ-008 | K34: High | L34: Functional | N34: Not Run | S34: File type and name not specified (Q-08) — record them.
A35: 31 | B35: CH2-10 | C35: Sdn Bhd / Bhd | D35: CH2 | E35: Guideline Email (UCD) | F35: Removed templates are not sent | G35: CH2-02 passed (Application Approved). Values from the run log (black window) block READY FOR MANUAL EMAIL CHECK and the expected-email file 04-runs/12341_CH2_<run>.md. | H35: 1. In Mailtrap, list every email to the run's addresses after the 'approved' time. | I35: 1. No email with subject 'RHB Branch Account Opening - …' (old Email Template 2). 2. No email with subject 'RHB Online Account Opening - …' without '/ Branch' (old Email Template 1). | J35: REQ-003 / REQ-004 removed, REQ-005 | K35: Medium | L35: Negative | N35: Not Run
A36: 32 | B36: CH2-11 | C36: Sdn Bhd / Bhd | D36: CH2 | E36: RHB Support Email | F36: RHB Support email — To and CC | G36: CH2-02 passed (Application Approved). Values from the run log (black window) block READY FOR MANUAL EMAIL CHECK and the expected-email file 04-runs/12341_CH2_<run>.md. | H36: 1. In Mailtrap, search the run's admin / director email (it is in CC of this email). 2. Open the email whose subject starts 'Approved eAuto Registration'. 3. Open its headers. | I36: 1. To = BIS.Support@rhbgroup.com. 2. CC contains the UCD email recorded in the Application AND apply@eauto.my. 3. Received after the 'approved' time. 4. The email is in Mailtrap only — nothing reached RHB (Q-17). | J36: REQ-006 | K36: High | L36: Functional | N36: Not Run
A37: 33 | B37: CH2-12 | C37: Sdn Bhd / Bhd | D37: CH2 | E37: RHB Support Email | F37: RHB Support email subject | G37: CH2-02 passed (Application Approved). Values from the run log (black window) block READY FOR MANUAL EMAIL CHECK and the expected-email file 04-runs/12341_CH2_<run>.md. | H37: 1. Open the RHB Support email. 2. Read the subject. | I37: 1. Subject = 'Approved eAuto Registration - <Company Name> - <BRN Number>'. 2. <Company Name> = the run's company name. 3. <BRN Number> = the number agreed in Q-05 (SRD example shows the 12-digit new number) — record which one. | J37: REQ-009 | K37: High | L37: Functional | N37: Not Run
A38: 34 | B38: CH2-13 | C38: Sdn Bhd / Bhd | D38: CH2 | E38: RHB Support Email | F38: RHB Support email body — values and wording | G38: CH2-02 passed (Application Approved). Values from the run log (black window) block READY FOR MANUAL EMAIL CHECK and the expected-email file 04-runs/12341_CH2_<run>.md. | H38: 1. Open the body. 2. Compare with sheet 'Expected Templates' → 'Email Template 3 — Body'. 3. Compare each value line with the Application. | I38: 1. Every paragraph present, in order, same wording (1 working day request, Reply All instruction, signature block). 2. Company Name / Business Registration Number / UCD Contact Person / Contact Number / Email Address show the Application's values (which contact: Q-04). 3. Does NOT contain 'The above company is not eligible for RHB's online account-opening process…'. | J38: REQ-009 | K38: High | L38: Functional | N38: Not Run | S38: The robot uses different name / mobile / email for Admin and Director, so this email shows which one the system takes (Q-04).
A39: 35 | B39: CH2-14 | C39: Sdn Bhd / Bhd | D39: CH2 | E39: RHB Support Email | F39: Appointment Letter attached to the RHB Support email | G39: CH2-02 passed (Application Approved). Values from the run log (black window) block READY FOR MANUAL EMAIL CHECK and the expected-email file 04-runs/12341_CH2_<run>.md. | H39: 1. Open the Attachments tab. 2. Download and open the attachment. | I39: 1. Exactly one attachment: the Appointment Letter for THIS Application. 2. It opens without error. | J39: REQ-008 | K39: High | L39: Functional | N39: Not Run
A40: 36 | B40: CH2-15 | C40: Sdn Bhd / Bhd | D40: CH2 | E40: Appointment Letter | F40: Appointment Letter layout and fixed text | G40: CH2-02 passed (Application Approved). Values from the run log (black window) block READY FOR MANUAL EMAIL CHECK and the expected-email file 04-runs/12341_CH2_<run>.md. | H40: 1. Open the letter from the guideline email. 2. Compare with sheet 'Expected Templates' → 'Appointment Letter' and with Sample_Appointment_Letter_v2.0. 3. Check header, body, signature and footer on every page. | I40: 1. Title 'LETTER OF CONFIRMATION OF REGISTRATION AS A USED CAR DEALER (UCD) UNDER eAUTO SDN. BHD. PLATFORM' (spacing: Q-10). 2. Letterhead: eAuto logo, 'eAuto Sdn Bhd 200401038456 (676967-T)', address, 'Tel: 03-2779 8893'. 3. Clauses 1–8 numbered, wording as the template; Clause 6 refers to 'Clause 5'. 4. Registration details table (UCD Name / Company Registration No. / UCD / Dealer Reference No.). 5. Signature image, 'CHIA KET MING', 'COO'; footer 'Website: www.eauto.my | Customer Service: 03-2779 8899 | Email: support@eauto.my'. 6. No layout break (cut text, overlap, blank page). | J40: REQ-007 | K40: Medium | L40: Functional | N40: Not Run
...

Sheet Test Data & Runs
A1: Runs = test data. Each run uses ONE real company (one company, one use). Companies go in EAINT-12341_eSim_Setup.xlsx, tab '1 Companies'.
A3: Run | B3: Business Type | C3: People | D3: TIN starts | E3: Purpose | F3: Registration no. format (letter) | G3: Test cases | H3: Pre-Application No | I3: Application No | J3: Run date / result
A4: CH1 | B4: Sdn Bhd / Bhd | C4: 4 directors, all Malaysian | D4: C | E4: Main run — do it first. Carries the extra checks CH1-20 (old email) and CH1-21 (hardcopy regression). | F4: <ROC no. with letter> (<12-digit no.>), e.g. 1511229-A (202301017307) | G4: CH1-01 … CH1-21 (21)
A5: CH2 | B5: Sdn Bhd / Bhd | C5: 3 directors: 2 Malaysian + 1 foreigner | D5: C | E5: REQ-005 Example 2 (foreign director) — must get the SAME email as CH1. | F5: <ROC no. with letter> (<12-digit no.>), e.g. 1511229-A (202301017307) | G5: CH2-01 … CH2-19 (19)
A6: CH3 | B6: Sole Proprietorship / Partnership | C6: 4 business owners, all Malaysian | D6: D | E6: Sole Proprietorship / Partnership normal case (REQ-005 Example 1). | F6: <ROB no. with letter> (<12-digit no.>), e.g. 003123456-X (202103123456) | G6: CH3-01 … CH3-19 (19)
A7: CH4 | B7: Sole Proprietorship / Partnership | C7: 5 business owners, all Malaysian | D7: D | E7: REQ-005 Example 2 (5 or more owners) — must get the SAME email as CH1. | F7: <ROB no. with letter> (<12-digit no.>), e.g. 003123456-X (202103123456) | G7: CH4-01 … CH4-19 (19)
A8: CH5 | B8: Sole Proprietorship / Partnership | C8: 4 business owners, all Malaysian | D8: D (or IG) | E8: Stops at Submitted — no-email checks, then a manual Revert to UCD. | F8: — | G8: CH5-01 … CH5-06 (6)
A9: CH6 | B9: LLP | C9: 4 partners, all Malaysian | D9: PT | E9: LLP is not in the eSimulator guide — confirm the eSim screen first. | F9: <LLP no. incl. -LGN> (<12-digit no.>), e.g. LLP0035174-LGN (202304001238) | G9: CH6-01 … CH6-19 (19)
A10: CH7 | B10: Business Trading (Sabah) | C10: 2 directors (typed by the robot) | D10: any valid (Q-20) | E10: Non-SSM. No eSim. Letter registration number expected result is TBC (red). | F10: TBC — no SSM details for Business Trading (Q-09) | G10: CH7-01 … CH7-19 (19)
A11: CH8 | B11: Business Trading (Sarawak) | C11: 2 directors (typed by the robot) | D11: any valid (Q-20) | E11: Non-SSM, Sarawak. No eSim. Letter registration number expected result is TBC (red). | F11: TBC — no SSM details for Business Trading (Q-09) | G11: CH8-01 … CH8-19 (19)
A13: Already used in v1.1 (never reuse): IP0581553-U, 003270488-X, 1267419-A.

Sheet Expected Templates
A1: Expected content — verbatim from SRD v1.3 (§2.2.4.1, §2.2.5.1, §2.2.5.2)
A3: Element | B3: Expected
A4: Email Template 1 — Sender | B4: Pending confirmation from Operations (not checked).
A5: Email Template 1 — Recipient | B5: To: Approved UCD email address captured in the Application. CC: apply@eauto.my
A6: Email Template 1 — Subject | B6: RHB Online / Branch Account Opening - [Application No] - [Company Name] E.g.: RHB Online / Branch Account Opening - NA50000802 - ABC Motors Sdn Bhd
A7: Email Template 1 — Body | B7: Dear Sir/Madam, We are pleased to confirm that your company's registration with eAuto has been approved. Application No: [Application No] Company Name: [Company Name] Please find the Appointment Letter attached for your reference. eAuto has notified the RHB Support Team regarding your approved registration. Kindly wait for RHB to provide the Letter of Offer and the relevant onboarding documents by email. If you do not receive the documents from RHB within three (3) working days, please contact us at apply@eauto.my. Once you have received the required documents from RHB, you may choose from the following two (2) options to apply for an RHB Islamic Current Account: Option 1 – Online Account Opening You may register online via the following link: [RHB Online Registration Link] Please note that the online account-opening option is applicable to companies with a maximum of four (4) authorised or main users. The account opening remains subject to RHB's prevailing eligibility requirements and approval. Upon completing the online application, please visit the RHB branch selected during your application within seven (7) days to complete the required verification and documentation process. Option 2 – Account Opening at RHB Branch Alternatively, you may visit your preferred RHB branch to apply for an RHB Islamic Current Account directly. The account opening will be subject to RHB's prevailing requirements, documentation and approval process. Once the RHB Islamic Current Account has been successfully opened, kindly provide eAuto with the relevant account confirmation document for the next stage of account activation through the Application Link below: [Application Link] For further assistance or inquiries, please contact us at apply@eauto.my. Thank you. Best regards, eAuto Sdn Bhd Level 15 Sunway Tower Jalan Ampang, 50450 Kuala Lumpur Customer Service: 03-27798899 WhatsApp: 012-2001324
A8: Email Template 1 — RHB link | B8: https://smecaonline.rhbgroup.com/sme/online?tag=campaign
A9: Email Template 3 — Sender | B9: Pending confirmation from Operations (not checked).
A10: Email Template 3 — Recipient | B10: To: BIS.Support@rhbgroup.com CC: Approved UCD email address captured in the Application, apply@eauto.my
A11: Email Template 3 — Subject | B11: Approved eAuto Registration - [Company Name] - [BRN Number] E.g.: Approved eAuto Registration - ABC Motors Sdn Bhd - 202401234567
A12: Email Template 3 — Body | B12: Dear RHB Support Team, We wish to inform you that the following company's registration with eAuto has been approved: Company Name: [Company Name] Business Registration Number: [BRN Number] UCD Contact Person: [Name] Contact Number: [Contact Number] Email Address: [UCD Email Address] Please find the Appointment Letter attached for your reference and further action. Kindly issue the Letter of Offer and relevant onboarding documents to the UCD within one (1) working day. The UCD has been copied in this email to ensure that it receives the documents directly. When responding, please use Reply All so that the UCD and eAuto remain included in the correspondence and can proceed with the subsequent account-opening arrangements. For further assistance or inquiries, please contact us at apply@eauto.my. Thank you. Best regards, eAuto Sdn Bhd Level 15 Sunway Tower Jalan Ampang, 50450 Kuala Lumpur Customer Service: 03-27798899 WhatsApp: 012-2001324
A13: Appointment Letter — Document Title | B13: LETTER OF CONFIRMATION OF REGISTRATION AS A USED CAR DEALER (UCD) UNDER eAUTO SDN. BHD. PLATFORM
A14: Appointment Letter — Letterhead | B14: eAuto logo; eAuto Sdn Bhd 200401038456 (676967-T); Level 15 Sunway Tower, Jalan Ampang, 50450 Kuala Lumpur; Tel: 03-2779 8893
... A37: Letter field [Pre-Application No] | B37: Pre-Application No (Pyymmdd/nnnnn)

Sheet Traceability
A1: Requirement → test cases (SRD v1.3)
A3: Requirement ID | B3: Item | C3: Status in v1.3 | D3: Acceptance Criteria (summary) | E3: # test cases | F3: Test cases
A4: EAINT-12341-REQ-001 | B4: Email Trigger | C4: Active | D4: Upon Application approval the UCD receives the guideline email; the existing approved application email with the 3 RHB documents is no longer sent; existing approval handling unchanged. | E4: =COUNTIF('Test Cases'!$J$4:$J$155,"*REQ-001*") | F4: CH1-02, CH1-04, CH1-05, CH1-19, CH1-20, CH1-21, CH2-02, CH2-04, CH2-05, CH2-19, CH3-02, CH3-04, CH3-05, CH3-19, CH4-02, CH4-04, CH4-05, CH4-19, CH5-02, CH5-04, CH5-05, CH5-06, CH6-02, CH6-04, CH6-05, CH6-19, CH7-02, CH7-04, CH7-05, CH7-19, CH8-02, CH8-04, CH8-05, CH8-19
A5: EAINT-12341-REQ-002 | B5: Email Recipient | C5: Active | D5: Guideline email addressed to the UCD email recorded in the approved Application. | E5: =COUNTIF('Test Cases'!$J$4:$J$155,"*REQ-002*") | F5: CH1-05, CH2-05, CH3-05, CH4-05, CH6-05, CH7-05, CH8-05
A6: EAINT-12341-REQ-003 | B6: Guideline Determination | C6: REMOVED in v1.3 | D6: Single email template, no template selection needed. | E6: =COUNTIF('Test Cases'!$J$4:$J$155,"*REQ-003*") | F6: CH1-10, CH2-10, CH3-10, CH4-10, CH6-10, CH7-10, CH8-10
A7: EAINT-12341-REQ-004 | B7: Data Source | C7: REMOVED in v1.3 | D7: Director count and nationality no longer read. | E7: =COUNTIF('Test Cases'!$J$4:$J$155,"*REQ-004*") | F7: CH1-10, CH2-10, CH3-10, CH4-10, CH6-10, CH7-10, CH8-10
A8: EAINT-12341-REQ-005 | B8: Email Template Content | C8: Updated in v1.3 | D8: Guideline email content matches Email Template 1 (§2.2.4.1) regardless of number of directors/owners and nationality (Example 1 and Example 2 both → Template 1). | E8: =COUNTIF('Test Cases'!$J$4:$J$155,"*REQ-005*") | F8: CH1-06, CH1-07, CH1-08, CH1-10, CH1-18, CH2-06, CH2-07, CH2-08, CH2-10, CH2-18, CH3-06, CH3-07, CH3-08, CH3-10, CH3-18, CH4-06, CH4-07, CH4-08, CH4-10, CH4-18, CH6-06, CH6-07, CH6-08, CH6-10, CH6-18, CH7-06, CH7-07, CH7-08, CH7-10, CH7-18, CH8-06, CH8-07, CH8-08, CH8-10, CH8-18
A9: EAINT-12341-REQ-006 | B9: Recipient and Copy | C9: Active | D9: Appointment Letter email To BIS.Support@rhbgroup.com; UCD email in CC. | E9: =COUNTIF('Test Cases'!$J$4:$J$155,"*REQ-006*") | F9: CH1-11, CH2-11, CH3-11, CH4-11, CH6-11, CH7-11, CH8-11
A10: EAINT-12341-REQ-007 | B10: Letter Generation | C10: Updated in v1.2 | D10: Appointment Letter per §2.2.5.2 generated with Application details pre-populated, no manual input. | E10: =COUNTIF('Test Cases'!$J$4:$J$155,"*REQ-007*") | F10: CH1-03, CH1-15, CH1-16, CH1-18, CH2-03, CH2-15, CH2-16, CH2-18, CH3-03, CH3-15, CH3-16, CH3-18, CH4-03, CH4-15, CH4-16, CH4-18, CH5-03, CH6-03, CH6-15, CH6-16, CH6-18, CH7-15, CH7-16, CH7-18, CH8-15, CH8-16, CH8-18
A11: EAINT-12341-REQ-008 | B11: Letter Attachment | C11: Updated in v1.2 | D11: Appointment Letter attached to the RHB Support email AND to the guideline email to the UCD. | E11: =COUNTIF('Test Cases'!$J$4:$J$155,"*REQ-008*") | F11: CH1-09, CH1-14, CH1-17, CH2-09, CH2-14, CH2-17, CH3-09, CH3-14, CH3-17, CH4-09, CH4-14, CH4-17, CH6-09, CH6-14, CH6-17, CH7-09, CH7-14, CH7-17, CH8-09, CH8-14, CH8-17
A12: EAINT-12341-REQ-009 | B12: Email Template Content | C12: Active (sentence withdrawn v1.1) | D12: RHB Support email content matches Email Template 3 (§2.2.5.1). | E12: =COUNTIF('Test Cases'!$J$4:$J$155,"*REQ-009*") | F12: CH1-12, CH1-13, CH1-18, CH2-12, CH2-13, CH2-18, CH3-12, CH3-13, CH3-18, CH4-12, CH4-13, CH4-18, CH6-12, CH6-13, CH6-18, CH7-12, CH7-13, CH7-18, CH8-12, CH8-13, CH8-18

Sheet Open Questions
A1: Open questions — 'xx-NN' = test NN of every run
A3: # | B3: Question | C3: Impact / interim handling | D3: Blocks | E3: Ask | F3: Status | G3: Answer | H3: Answered by / date
A4: Q-01 | B4: The email template document V3.0 (Yeng, 29.09) ends at 'For further assistance or inquiries, please contact us at apply@eauto.my.' with no 'Thank you / Best regards / eAuto Sdn Bhd / address / Customer Service / WhatsApp' block. SRD v1.3 §2.2.4.1 keeps that block. Which one is expected? | C4: Until answered the SRD is used (it is the baseline). A missing signature will be reported, not failed silently. | D4: xx-07 | E4: BA (Chee Mei Jia) / Operations | F4: Open
A5: Q-02 | B5: The template document's heading 'UCD ONLINE REGISTRATION (ONLINE & BRANCH COMBINED)' — confirm it is only the document title and NOT the email subject (SRD subject: 'RHB Online / Branch Account Opening - [Application No] - [Company Name]'). | C5: xx-06 uses the SRD subject. | D5: xx-06 | E5: BA | F5: Open
A6: Q-03 | B6: [Application Link] — which link is it and where should it land for an APPROVED Application (the same Application form link emailed at Pre-Application approval, the Registration Document step, something else)? Any expiry? | C6: xx-08 can only check 'clickable, not an error' until answered. | D6: xx-08 | E6: BA / Dev | F6: Open
A7: Q-04 | B7: Which fields feed (a) the 'UCD email address captured in the Application' (To of Email Template 1, CC of Email Template 3, Email Address in Template 3) and (b) Template 3 'UCD Contact Person: [Name]' and 'Contact Number': the Admin In Charge on the Pre-Application, or the Director / Business Owner in Charge on Application step 3? | C7: The chain now uses different name / mobile / email for the two, so the first run will SHOW what the system uses — but QA needs the intended answer to pass/fail. | D7: xx-05, xx-11, xx-13 | E7: BA / Dev | F7: Open
A8: Q-05 | B8: Template 3 [BRN Number] — new BRN (12-digit, as the SRD example '202401234567' suggests) or old BRN? What is shown for Business Trading (licence no.)? | C8: xx-12/xx-13 record the value shown. | D8: xx-12, xx-13, xx-11–14 | E8: BA | F8: Open
A9: Q-06 | B9: Appointment Letter [Company Address] — 'company address captured in the Application': which address (the showroom address carried from the Pre-Application, or another address field)? Single line or multi-line? | C9: xx-16 compares against the showroom address until answered. | D9: xx-16 | E9: BA / Dev | F9: Open
A10: Q-07 | B10: The sample letter keeps square brackets in the output: 'Our Ref: [eAuto/OPS/UCD/NA69001196/2026]' and '[1511229-A (202301017307)]' in the recipient block and Clause 1, but not in the Clause 4 table. Are the outer brackets literal (expected in the generated letter) or a sample artefact? | C10: Affects pass/fail of xx-16 and xx-18. | D10: xx-16, xx-18 | E10: BA / Operations | F10: Open
A11: Q-08 | B11: Appointment Letter file format (PDF or DOCX) and attachment file name convention? | C11: Record what is received. | D11: xx-09, xx-14, xx-17 | E11: BA / Dev | F11: Open
A12: Q-09 | B12: Business Trading (no SSM details): what should the letter show for [Old BRN] ([New BRN]) — the trading licence number? blank? | C12: CH7/CH8-16 is RED until answered. | D12: CH7/CH8-16 | E12: BA | F12: Open
A13: Q-10 | B13: Letter title: SRD v1.3 'UNDER eAUTO SDN. BHD. PLATFORM' vs template .docx 'UNDER eAUTO SDN. BHD.PLATFORM' (no space). Which is correct? | C13: Minor — will be raised as cosmetic if the output differs from the SRD. | D13: xx-15 | E13: BA | F13: Open
A14: Q-11 | B14: Letter date / [YYYY]: in which time zone is the 'Application approval date' taken (MYT)? Any rule for approvals around midnight / year end? | C14: Low risk; noted. | D14: xx-16 | E14: Dev | F14: Open
A15: Q-12 | B15: Sender (From) for all three emails is still 'Pending confirmation from Operations' in v1.3. Has it been decided? | C15: No case asserts From until confirmed. | D15: xx-05, xx-11 | E15: Operations | F15: Open
